Workbook
Name Slicer_CATEGORY: #N/A
Name Slicer_CATEGORY2: #N/A
Name Slicer_genre: #N/A
Name Slicer_STOCK_STATUS: #N/A

Sheet 01_Raw_Data
A1: month | B1: from | C1: to | D1: sku | E1: qty | F1: unit_cost | G1: unit_price | H1: extended_cost | I1: extended_retail | J1: dataset | L1: {=L1:M41Book Title} -> #NAME? | M1: Author | N1: Category | O1: Price (TK) | P1: Stock Status | Q1: Copies Left | R1: Book Length (Pages) | S1: Edition | T1: Publication | U1: Wished Users | V1: Discount Offer | W1: Ratings | X1: Reviews
A2: 43466 | B2: YYC-WH | C2: YYC-DT | D2: BK1000 | E2: 19 | F2: 8.09 | G2: 18.92 | H2: 153.71 | I2: 359.48 | J2: bookstore_inventory | L2: Sapiens A Brief History Of Humankind | M2: Yuval Noah Harari | N2: History and Tradition | O2: 1258 | P2: In Stock | Q2: 4 | R2: 4+R2:S3398 | S2: 1st Published | T2: Vintage Books (India) | U2: 386 | V2: Yes | W2: 39 | X2: 16
A3: 43466 | B3: YYC-WH | C3: YYC-NW | D3: BK1000 | E3: 10 | F3: 8.09 | G3: 18.92 | H3: 80.9 | I3: 189.2 | J3: bookstore_inventory | L3: The Intelligent Investor | M3: Benjamin Graham | N3: Business, Investment and Economics | O3: 1598 | P3: In Stock | Q3: 6 | R3: 640 | S3: 8th Impression | T3: Harpercollins Publishers (India) | U3: 531 | V3: Yes | W3: 30 | X3: 25
A4: 43466 | B4: YYC-WH | C4: YYC-SE | D4: BK1000 | E4: 7 | F4: 8.09 | G4: 18.92 | H4: 56.63 | I4: 132.44 | J4: bookstore_inventory | L4: Madinah Arabic Reader 1 | M4: Dr. V. Abdur Rahim | N4: Islamic Books | O4: 528 | P4: In Stock | Q4: 21 | R4: 80 | S4: 1st Edition 2011 | T4: Goodword Books (India) | U4: N/A | V4: Yes | W4: 6 | X4: 3
A5: 43466 | B5: YYC-WH | C5: YYC-DT | D5: BK1001 | E5: 21 | F5: 10.75 | G5: 24.49 | H5: 225.75 | I5: 514.29 | J5: bookstore_inventory | L5: The Quran | M5: M.A.S. Abdel Haleem (Translator) | N5: Islamic Books | O5: 950 | P5: In Stock | Q5: 38 | R5: 512 | S5: Reissue Edition | T5: Oxford University Press, USA | U5: N/A | V5: Yes | W5: 19 | X5: 5
A6: 43466 | B6: YYC-WH | C6: YYC-NW | D6: BK1001 | E6: 13 | F6: 10.75 | G6: 24.49 | H6: 139.75 | I6: 318.37 | J6: bookstore_inventory | L6: Let Us C, 19th Edition | M6: Yashavant Kanetkar | N6: Computer Science & Engineering | O6: 718 | P6: In Stock | Q6: 18 | R6: 492 | S6: 19th Edition | T6: BPB Publications (India) | U6: N/A | V6: Yes | W6: 3 | X6: 1
A7: 43466 | B7: YYC-WH | C7: YYC-SE | D7: BK1001 | E7: 6 | F7: 10.75 | G7: 24.49 | H7: 64.5 | I7: 146.94 | J7: bookstore_inventory | L7: 400 Days | M7: Chetan Bhagat | N7: Novel | O7: 450 | P7: In Stock | Q7: 50+ | R7: 344 | S7: Published | T7: Westland (India) | U7: N/A | V7: Yes | W7: 9 | X7: 2
A8: 43466 | B8: YYC-WH | C8: YYC-DT | D8: BK1002 | E8: 17 | F8: 15.1 | G8: 31.89 | H8: 256.7 | I8: 542.13 | J8: bookstore_inventory | L8: War And Peace | M8: Leo Tolstoy, Richard Pevear (Translator), Larissa Volokhonsky (Translator) | N8: Novel | O8: 1618 | P8: In Stock | Q8: 11 | R8: 1276 | S8: 1st Edition | T8: Vintage Classics (India) | U8: 108 | V8: Yes | W8: 9 | X8: 2
A9: 43466 | B9: YYC-WH | C9: YYC-NW | D9: BK1002 | E9: 9 | F9: 15.1 | G9: 31.89 | H9: 135.9 | I9: 287.01 | J9: bookstore_inventory | L9: Ecotourism | M9: Harish Bhat , B.S. Badan | N9: Tourism and Hospitality | O9: 965 | P9: Out stock | Q9: 0 | R9: 345 | S9: Commonwealth Pub. | V9: No | W9: 0 | X9: 0
A10: 43466 | B10: YYC-WH | C10: YYC-SE | D10: BK1002 | E10: 7 | F10: 15.1 | G10: 31.89 | H10: 105.7 | I10: 223.23 | J10: bookstore_inventory | L10: Managing Tourism and Hospitality Services | M10: Gianna Moscardo (Editor), Bruce Prideaux (Editor), Eric Laws (Editor) | N10: Tourism and Hospitality | O10: 17487 | P10: In Stock | Q10: 3 | R10: 338 | S10: Edition | T10: Cabi Publishing (India) | U10: N/A | V10: Yes | W10: 1 | X10: 0
A11: 43466 | B11: YYC-WH | C11: YYC-DT | D11: BK1003 | E11: 21 | F11: 14.35 | G11: 28.58 | H11: 301.35 | I11: 600.18 | J11: bookstore_inventory | L11: Tata Stories | M11: Harish Bhat | N11: Foreign Language Books | O11: 1078 | P11: In Stock | Q11: 5 | R11: 202 | S11: 1st Edition | T11: Portfolio Penguin (India) | U11: N/A | V11: Yes | W11: 2 | X11: 0
A12: 43466 | B12: YYC-WH | C12: YYC-NW | D12: BK1003 | E12: 12 | F12: 14.35 | G12: 28.58 | H12: 172.2 | I12: 342.96 | J12: bookstore_inventory | L12: Elon Musk | M12: Walter Isaacson | N12: Biographies, Memories & Interviews | O12: 2698 | P12: In Stock | Q12: 2 | R12: 688 | S12: 45181 | T12: Simon & Schuster Ltd (India) | U12: N/A | V12: Yes | W12: 2 | X12: 0
A13: 43466 | B13: YYC-WH | C13: YYC-SE | D13: BK1003 | E13: 10 | F13: 14.35 | G13: 28.58 | H13: 143.5 | I13: 285.8 | J13: bookstore_inventory | L13: How Harsh Mariwala ?Groomed? Marico | M13: R. Gopalakrishnan , M. Suresh Rao | N13: Business, Investment and Economics | O13: 711 | P13: In Stock | Q13: 2 | R13: 146 | S13: 1st Edition | T13: Rupa Publications India | U13: N/A | V13: Yes | W13: 1 | X13: 0
A14: 43466 | B14: YYC-WH | C14: YYC-DT | D14: BK1004 | E14: 8 | F14: 7.85 | G14: 19.61 | H14: 62.8 | I14: 156.88 | J14: bookstore_inventory | L14: TataLog Eight Modern Stories from a Timeless Institution | M14: Harish Bhat | N14: Business, Investment and Economics | O14: 898 | P14: In Stock | Q14: 5 | R14: 224 | S14: Edition | T14: Penguin Business (India) | U14: N/A | V14: Yes | W14: 3 | X14: 0
A15: 43466 | B15: YYC-WH | C15: YYC-NW | D15: BK1004 | E15: 12 | F15: 7.85 | G15: 19.61 | H15: 94.2 | I15: 235.32 | J15: bookstore_inventory | L15: Good Economics for Hard Times | M15: Abhijit V. Banerjee , Esther Duflo | N15: Business, Investment and Economics | O15: 998 | P15: In Stock | Q15: 8 | R15: 402 | S15: Edition | T15: Juggernaut (India) | U15: N/A | V15: Yes | W15: 5 | X15: 4
A16: 43466 | B16: YYC-WH | C16: YYC-SE | D16: BK1004 | E16: 7 | F16: 7.85 | G16: 19.61 | H16: 54.95 | I16: 137.27 | J16: bookstore_inventory | L16: The Wealth of Nations : Fingerprint | M16: Adam Smith | N16: Business, Investment and Economics | O16: 1498 | P16: In Stock | Q16: 5 | R16: 1144 | S16: 1st Published | T16: Fingerprint Publishing (India) | U16: N/A | V16: Yes | W16: 0 | X16: 0
A17: 43466 | B17: YYC-WH | C17: YYC-DT | D17: BK1005 | E17: 12 | F17: 15.79 | G17: 33.13 | H17: 189.48 | I17: 397.56 | J17: bookstore_inventory | L17: Train to Pakistan | M17: Khushwant Singh | N17: Novel | O17: 450 | P17: In Stock | Q17: 4 | R17: 190 | S17: 1st Edition | T17: Penguin Books (India) | U17: N/A | V17: Yes | W17: 11 | X17: 2
A18: 43466 | B18: YYC-WH | C18: YYC-NW | D18: BK1005 | E18: 9 | F18: 15.79 | G18: 33.13 | H18: 142.11 | I18: 298.17 | J18: bookstore_inventory | L18: One Hundred Years of Solitude | M18: Gabriel Garcia Marquez | N18: Novel | O18: 798 | P18: In Stock | Q18: 7 | R18: 422 | S18: 5th Edition | T18: Penguin Books (India) | U18: 374 | V18: Yes | W18: 23 | X18: 5
A19: 43466 | B19: YYC-WH | C19: YYC-SE | D19: BK1005 | E19: 13 | F19: 15.79 | G19: 33.13 | H19: 205.27 | I19: 430.69 | J19: bookstore_inventory | L19: A Thousand Splendid Suns | M19: Khaled Hosseini | N19: Novel | O19: 1198 | P19: In Stock | Q19: 8 | R19: 419 | S19: 1st Edition | T19: Bloomsbury Publishing (India) | U19: 277 | V19: Yes | W19: 27 | X19: 13
A20: 43466 | B20: YYC-WH | C20: YYC-DT | D20: BK1006 | E20: 10 | F20: 8.69 | G20: 18.39 | H20: 86.9 | I20: 183.9 | J20: bookstore_inventory | L20: Ikigai | M20: Hector Garcia, Francesc Miralles | N20: Self-help and meditation | O20: 1100 | P20: In Stock | Q20: 32 | R20: 208 | S20: 1st Edition | T20: Random House UK | U20: N/A | V20: Yes | W20: 10 | X20: 4
A21: 43466 | B21: YYC-WH | C21: YYC-NW | D21: BK1006 | E21: 4 | F21: 8.69 | G21: 18.39 | H21: 34.76 | I21: 73.56 | J21: bookstore_inventory | L21: Zero to One: Notes on Start Ups, or How to Build the Future | M21: Peter Thiel, Blake Masters | N21: Self-help and meditation | O21: 1198 | P21: In Stock | Q21: 13 | R21: 210 | S21: Edition | T21: Virgin Books (India) | U21: 308 | V21: Yes | W21: 13 | X21: 6
A22: 43466 | B22: YYC-WH | C22: YYC-SE | D22: BK1006 | E22: 5 | F22: 8.69 | G22: 18.39 | H22: 43.45 | I22: 91.95 | J22: bookstore_inventory | L22: Atomic Habits | M22: James Clear | N22: Self-help and meditation | O22: 1598 | P22: In Stock | Q22: 9 | R22: 288 | S22: 1st Published | T22: Random House Business Books (India) | U22: 412 | V22: Yes | W22: 19 | X22: 4
A23: 43466 | B23: YYC-WH | C23: YYC-DT | D23: BK1007 | E23: 11 | F23: 8.69 | G23: 16.64 | H23: 95.59 | I23: 183.04 | J23: bookstore_inventory | L23: Mein Kampf | M23: Adolf Hitler | N23: International Political Personality | O23: 798 | P23: In Stock | Q23: 17 | R23: 560 | S23: Published | T23: Fingerprint Publishing (India) | U23: N/A | V23: Yes | W23: 17 | X23: 5
A24: 43466 | B24: YYC-WH | C24: YYC-NW | D24: BK1007 | E24: 7 | F24: 8.69 | G24: 16.64 | H24: 60.83 | I24: 116.48 | J24: bookstore_inventory | L24: The Post American World And The Rise Of The Rest | M24: Fareed Zakaria | N24: International Politics | O24: 2343 | P24: In Stock | Q24: 1 | R24: 292 | S24: 1st Edition | T24: Penguin Books (India) | U24: N/A | V24: Yes | W24: 10 | X24: 2
A25: 43466 | B25: YYC-WH | C25: YYC-SE | D25: BK1007 | E25: 7 | F25: 8.69 | G25: 16.64 | H25: 60.83 | I25: 116.48 | J25: bookstore_inventory | L25: The Old Man and The Sea | M25: Ernest Hemingway | N25: Novel | O25: 150 | P25: In Stock | Q25: 0 | R25: 104 | S25: 2nd Edition | T25: Friend's Book Corner | U25: 453 | V25: Yes | W25: 73 | X25: 54
A26: 43466 | B26: YYC-WH | C26: YYC-DT | D26: BK1008 | E26: 15 | F26: 12.44 | G26: 29.31 | H26: 186.6 | I26: 439.65 | J26: bookstore_inventory | L26: Metamorphosis | M26: Franz Kafka, David Wyllie (Translator) | N26: Novel | O26: 258 | P26: In Stock | Q26: 20 | R26: 100 | S26: Published | T26: Fingerprint Publishing (India) | U26: N/A | V26: Yes | W26: 29 | X26: 8
A27: 43466 | B27: YYC-WH | C27: YYC-NW | D27: BK1008 | E27: 1 | F27: 12.44 | G27: 29.31 | H27: 12.44 | I27: 29.31 | J27: bookstore_inventory | L27: Animal Farm | M27: George Orwell | N27: Novel | O27: 258 | P27: In Stock | Q27: 33 | R27: 95 | S27: 1st Edition | T27: Fingerprint Publishing (India) | U27: 384 | V27: Yes | W27: 44 | X27: 17
A28: 43466 | B28: YYC-WH | C28: YYC-SE | D28: BK1008 | E28: 4 | F28: 12.44 | G28: 29.31 | H28: 49.76 | I28: 117.24 | J28: bookstore_inventory | L28: The Girl in Room 105 | M28: Chetan Bhagat | N28: Novel | O28: 450 | P28: In Stock | Q28: 5 | R28: 308 | S28: Published | T28: Harpercollins Publishers (India) | U28: 252 | V28: Yes | W28: 36 | X28: 17
A29: 43466 | B29: YYC-WH | C29: YYC-DT | D29: BK1009 | E29: 20 | F29: 13.12 | G29: 29.99 | H29: 262.4 | I29: 599.8 | J29: bookstore_inventory | L29: The Alchemist | M29: Paulo Coelho | N29: Novel | O29: 798 | P29: In Stock | Q29: 44 | R29: 172 | S29: 1st Edition | T29: Harpercollins Publishers (India) | U29: 1470 | V29: Yes
A30: 43466 | B30: YYC-WH | C30: YYC-NW | D30: BK1009 | E30: 13 | F30: 13.12 | G30: 29.99 | H30: 170.56 | I30: 389.87 | J30: bookstore_inventory | L30: The Startup Wife | M30: Tahmima Anam | N30: Novel | O30: 1078 | P30: In Stock | Q30: 1 | R30: 304 | S30: Published | T30: Penguin Books (India) | U30: N/A | V30: Yes | W30: 4 | X30: 0
A31: 43466 | B31: YYC-WH | C31: YYC-SE | D31: BK1009 | E31: 8 | F31: 13.12 | G31: 29.99 | H31: 104.96 | I31: 239.92 | J31: bookstore_inventory | L31: My Devotion | M31: Julia Kerninon, Alison Anderson | N31: Novel | O31: 1530 | P31: In Stock | Q31: 1 | R31: 272 | S31: 27th August 2020 | T31: Europa Editions | U31: N/A | V31: Yes
A32: 43466 | B32: YYC-WH | C32: YYC-DT | D32: BK1010 | E32: 7 | F32: 12.96 | G32: 25.33 | H32: 90.72 | I32: 177.31 | J32: bookstore_inventory | L32: How to Win Friends and Influence People | M32: Dale Carnegie | N32: Self-help and meditation | O32: 350 | P32: In Stock | Q32: 27 | R32: 4+R2:S3399 | S32: 2nd Published | T32: Vintage Books (India) | U32: 967 | V32: Yes | W32: 85 | X32: 29
A33: 43466 | B33: YYC-WH | C33: YYC-NW | D33: BK1010 | E33: 11 | F33: 12.96 | G33: 25.33 | H33: 142.56 | I33: 278.63 | J33: bookstore_inventory | L33: The Power Of Positive Thinking | M33: Dr. Norman Vincent Peale | N33: Self-help and meditation | O33: 398 | P33: In Stock | Q33: 4 | R33: 194.28079 | S33: 9th Impression | T33: Harpercollins Publishers (India) | U33: 528 | V33: Yes | W33: 26 | X33: 9
A34: 43466 | B34: YYC-WH | C34: YYC-SE | D34: BK1010 | E34: 7 | F34: 12.96 | G34: 25.33 | H34: 90.72 | I34: 177.31 | J34: bookstore_inventory | L34: Who Moved My Cheese? | M34: Spencer Johnson | N34: Self-help and meditation | O34: 405 | P34: In Stock | Q34: 40 | R34: 96 | S34: Published | T34: Vermilion London (India) | U34: 860 | V34: Yes | W34: 55 | X34: 25
A35: 43466 | B35: YYC-WH | C35: YYC-DT | D35: BK1011 | E35: 15 | F35: 7.1 | G35: 13.19 | H35: 106.5 | I35: 197.85 | J35: bookstore_inventory | L35: Think and Grow Rich | M35: Napoleon Hill | N35: Self-help and meditation | O35: 450 | P35: In Stock | Q35: 50+ | R35: 332 | S35: 1st Published | T35: Amazing Reads (India) | U35: 648 | V35: Yes | W35: 50 | X35: 26
A36: 43466 | B36: YYC-WH | C36: YYC-NW | D36: BK1011 | E36: 8 | F36: 7.1 | G36: 13.19 | H36: 56.8 | I36: 105.52 | J36: bookstore_inventory | L36: The Power of Your Subconscious Mind | M36: Dr. Joseph Murphy | N36: Self-help and meditation | O36: 500 | P36: In Stock | Q36: 0 | R36: 312 | S36: Edition | T36: Amazing Reads (India) | U36: 692 | V36: No | W36: 35 | X36: 17
A37: 43466 | B37: YYC-WH | C37: YYC-SE | D37: BK1011 | E37: 11 | F37: 7.1 | G37: 13.19 | H37: 78.1 | I37: 145.09 | J37: bookstore_inventory | L37: How To Talk To Anyone | M37: Leil Lowndes | N37: Self-help and meditation | O37: 798 | P37: In Stock | Q37: 37 | R37: 352 | S37: 1st | T37: Harper Element (India) | U37: 388 | V37: Yes | W37: 5 | X37: 3
A38: 43466 | B38: YYC-WH | C38: YYC-DT | D38: BK1012 | E38: 19 | F38: 16.53 | G38: 37.63 | H38: 314.07 | I38: 714.97 | J38: bookstore_inventory | L38: How To Instantly Connect With Anyone | M38: Leil Lowndes | N38: Self-help and meditation | O38: 855 | P38: In Stock | Q38: 0 | R38: 336 | S38: 1st Edition | T38: McGraw-Hill (India) | U38: N/A | V38: No | W38: 0 | X38: 0
A39: 43466 | B39: YYC-WH | C39: YYC-NW | D39: BK1012 | E39: 14 | F39: 16.53 | G39: 37.63 | H39: 231.42 | I39: 526.82 | J39: bookstore_inventory | L39: Winning | M39: Jack Welch, Suzy Welch | N39: Self-help and meditation | O39: 900 | P39: In Stock | Q39: 2 | R39: 372 | S39: 16th Impression | T39: Harpercollins Publishers (India) | U39: N/A | V39: Yes | W39: 27 | X39: 13
A40: 43466 | B40: YYC-WH | C40: YYC-SE | D40: BK1012 | E40: 10 | F40: 16.53 | G40: 37.63 | H40: 165.3 | I40: 376.3 | J40: bookstore_inventory | L40: The Art of War | M40: Sun Tzu | N40: War Tactics and Foreign Policy | O40: 178 | P40: In Stock | Q40: 11 | R40: 100 | S40: 1st Edition | T40: Fingerprint Publishing (India) | U40: 425 | V40: Yes | W40: 1 | X40: 0
...

Sheet 02_Clean_Data
A1: month | B1: from | C1: to | D1: sku | E1: quantity | F1: unit cost | G1: unit price | H1: extend cost | I1: extend price | J1: revenue | K1: profit | L1: book name | M1: author | N1: genre | O1: publication | P1: length | Q1: edition | R1: stock status | S1: copies left | T1: rating
A2: 43466 | B2: YYC-WH | C2: YYC-DT | D2: BK1000 | E2: 19 | F2: 8.09 | G2: 19 | H2: 153.71 | I2: 359.48 | J2: =(Table1[[#This Row],[unit price]]*Table1[[#This Row],[quantity]]) -> 361 | K2: =(Table1[[#This Row],[extend price]]-Table1[[#This Row],[extend cost ]]) -> 205.77 | L2: Sapiens A Brief History Of Humankind | M2: Yuval Noah Harari | N2: History and Tradition | O2: Vintage Books (India) | P2: 483 | Q2: 1st Published | R2: In Stock | S2: 4 | T2: 39
A3: 43466 | B3: YYC-WH | C3: YYC-NW | D3: BK1000 | E3: 10 | F3: 8.09 | G3: 10 | H3: 80.9 | I3: 189.2 | J3: =(Table1[[#This Row],[unit price]]*Table1[[#This Row],[quantity]]) -> 100 | K3: =(Table1[[#This Row],[extend price]]-Table1[[#This Row],[extend cost ]]) -> 108.3 | L3: The Intelligent Investor | M3: Benjamin Graham | N3: Business, Investment and Economics | O3: Harpercollins Publishers (India) | P3: 640 | Q3: 8th Impression | R3: In Stock | S3: 6 | T3: 30
A4: 43466 | B4: YYC-WH | C4: YYC-SE | D4: BK1000 | E4: 7 | F4: 8.09 | G4: 7 | H4: 56.63 | I4: 132.44 | J4: =(Table1[[#This Row],[unit price]]*Table1[[#This Row],[quantity]]) -> 49 | K4: =(Table1[[#This Row],[extend price]]-Table1[[#This Row],[extend cost ]]) -> 75.81 | L4: Madinah Arabic Reader 1 | M4: Dr. V. Abdur Rahim | N4: Islamic Books | O4: Goodword Books (India) | P4: 80 | Q4: 1st Edition 2011 | R4: In Stock | S4: 21 | T4: 6
A5: 43466 | B5: YYC-WH | C5: YYC-DT | D5: BK1001 | E5: 21 | F5: 10.75 | G5: 21 | H5: 225.75 | I5: 514.29 | J5: =(Table1[[#This Row],[unit price]]*Table1[[#This Row],[quantity]]) -> 441 | K5: =(Table1[[#This Row],[extend price]]-Table1[[#This Row],[extend cost ]]) -> 288.54 | L5: The Quran | M5: M.A.S. Abdel Haleem (Translator) | N5: Islamic Books | O5: Oxford University Press, USA | P5: 512 | Q5: Reissue Edition | R5: In Stock | S5: 38 | T5: 19
A6: 43466 | B6: YYC-WH | C6: YYC-NW | D6: BK1001 | E6: 13 | F6: 10.75 | G6: 13 | H6: 139.75 | I6: 318.37 | J6: =(Table1[[#This Row],[unit price]]*Table1[[#This Row],[quantity]]) -> 169 | K6: =(Table1[[#This Row],[extend price]]-Table1[[#This Row],[extend cost ]]) -> 178.62 | L6: Let Us C, 19th Edition | M6: Yashavant Kanetkar | N6: Computer Science & Engineering | O6: BPB Publications (India) | P6: 492 | Q6: 19th Edition | R6: In Stock | S6: 18 | T6: 3
A7: 43466 | B7: YYC-WH | C7: YYC-SE | D7: BK1001 | E7: 6 | F7: 10.75 | G7: 6 | H7: 64.5 | I7: 146.94 | J7: =(Table1[[#This Row],[unit price]]*Table1[[#This Row],[quantity]]) -> 36 | K7: =(Table1[[#This Row],[extend price]]-Table1[[#This Row],[extend cost ]]) -> 82.44 | L7: 400 Days | M7: Chetan Bhagat | N7: Novel | O7: Westland (India) | P7: 344 | Q7: Published | R7: In Stock | S7: 50+ | T7: 9
A8: 43466 | B8: YYC-WH | C8: YYC-DT | D8: BK1002 | E8: 17 | F8: 15.1 | G8: 17 | H8: 256.7 | I8: 542.13 | J8: =(Table1[[#This Row],[unit price]]*Table1[[#This Row],[quantity]]) -> 289 | K8: =(Table1[[#This Row],[extend price]]-Table1[[#This Row],[extend cost ]]) -> 285.43 | L8: War And Peace | M8: Leo Tolstoy, Richard Pevear (Translator), Larissa Volokhonsky (Translator) | N8: Novel | O8: Vintage Classics (India) | P8: 1276 | Q8: 1st Edition | R8: In Stock | S8: 11 | T8: 9
A9: 43466 | B9: YYC-WH | C9: YYC-NW | D9: BK1002 | E9: 9 | F9: 15.1 | G9: 9 | H9: 135.9 | I9: 287.01 | J9: =(Table1[[#This Row],[unit price]]*Table1[[#This Row],[quantity]]) -> 81 | K9: =(Table1[[#This Row],[extend price]]-Table1[[#This Row],[extend cost ]]) -> 151.11 | L9: Ecotourism | M9: Harish Bhat , B.S. Badan | N9: Tourism and Hospitality | O9: Cabi Publishing (India) | P9: 345 | Q9: Commonwealth Pub. | R9: Out stock | S9: 0 | T9: 0
A10: 43466 | B10: YYC-WH | C10: YYC-SE | D10: BK1002 | E10: 7 | F10: 15.1 | G10: 7 | H10: 105.7 | I10: 223.23 | J10: =(Table1[[#This Row],[unit price]]*Table1[[#This Row],[quantity]]) -> 49 | K10: =(Table1[[#This Row],[extend price]]-Table1[[#This Row],[extend cost ]]) -> 117.53 | L10: Managing Tourism and Hospitality Services | M10: Gianna Moscardo (Editor), Bruce Prideaux (Editor), Eric Laws (Editor) | N10: Tourism and Hospitality | O10: Cabi Publishing (India) | P10: 338 | Q10: Edition | R10: In Stock | S10: 3 | T10: 1
A11: 43466 | B11: YYC-WH | C11: YYC-DT | D11: BK1003 | E11: 21 | F11: 14.35 | G11: 21 | H11: 301.35 | I11: 600.18 | J11: =(Table1[[#This Row],[unit price]]*Table1[[#This Row],[quantity]]) -> 441 | K11: =(Table1[[#This Row],[extend price]]-Table1[[#This Row],[extend cost ]]) -> 298.83 | L11: Tata Stories | M11: Harish Bhat | N11: Foreign Language Books | O11: Portfolio Penguin (India) | P11: 202 | Q11: 1st Edition | R11: In Stock | S11: 5 | T11: 2
A12: 43466 | B12: YYC-WH | C12: YYC-NW | D12: BK1003 | E12: 12 | F12: 14.35 | G12: 12 | H12: 172.2 | I12: 342.96 | J12: =(Table1[[#This Row],[unit price]]*Table1[[#This Row],[quantity]]) -> 144 | K12: =(Table1[[#This Row],[extend price]]-Table1[[#This Row],[extend cost ]]) -> 170.76 | L12: Elon Musk | M12: Walter Isaacson | N12: Biographies, Memories & Interviews | O12: Simon & Schuster Ltd (India) | P12: 688 | Q12: published | R12: In Stock | S12: 2 | T12: 2
A13: 43466 | B13: YYC-WH | C13: YYC-SE | D13: BK1003 | E13: 10 | F13: 14.35 | G13: 10 | H13: 143.5 | I13: 285.8 | J13: =(Table1[[#This Row],[unit price]]*Table1[[#This Row],[quantity]]) -> 100 | K13: =(Table1[[#This Row],[extend price]]-Table1[[#This Row],[extend cost ]]) -> 142.3 | L13: How Harsh Mariwala ?Groomed? Marico | M13: R. Gopalakrishnan , M. Suresh Rao | N13: Business, Investment and Economics | O13: Rupa Publications India | P13: 146 | Q13: 1st Edition | R13: In Stock | S13: 2 | T13: 1
A14: 43466 | B14: YYC-WH | C14: YYC-DT | D14: BK1004 | E14: 8 | F14: 7.85 | G14: 8 | H14: 62.8 | I14: 156.88 | J14: =(Table1[[#This Row],[unit price]]*Table1[[#This Row],[quantity]]) -> 64 | K14: =(Table1[[#This Row],[extend price]]-Table1[[#This Row],[extend cost ]]) -> 94.08 | L14: TataLog Eight Modern Stories from a Timeless Institution | M14: Harish Bhat | N14: Business, Investment and Economics | O14: Penguin Business (India) | P14: 224 | Q14: Edition | R14: In Stock | S14: 5 | T14: 3
A15: 43466 | B15: YYC-WH | C15: YYC-NW | D15: BK1004 | E15: 12 | F15: 7.85 | G15: 12 | H15: 94.2 | I15: 235.32 | J15: =(Table1[[#This Row],[unit price]]*Table1[[#This Row],[quantity]]) -> 144 | K15: =(Table1[[#This Row],[extend price]]-Table1[[#This Row],[extend cost ]]) -> 141.12 | L15: Good Economics for Hard Times | M15: Abhijit V. Banerjee , Esther Duflo | N15: Business, Investment and Economics | O15: Juggernaut (India) | P15: 402 | Q15: Edition | R15: In Stock | S15: 8 | T15: 5
A16: 43466 | B16: YYC-WH | C16: YYC-SE | D16: BK1004 | E16: 7 | F16: 7.85 | G16: 7 | H16: 54.95 | I16: 137.27 | J16: =(Table1[[#This Row],[unit price]]*Table1[[#This Row],[quantity]]) -> 49 | K16: =(Table1[[#This Row],[extend price]]-Table1[[#This Row],[extend cost ]]) -> 82.32 | L16: The Wealth of Nations : Fingerprint | M16: Adam Smith | N16: Business, Investment and Economics | O16: Fingerprint Publishing (India) | P16: 1144 | Q16: 1st Published | R16: In Stock | S16: 5 | T16: 0
A17: 43466 | B17: YYC-WH | C17: YYC-DT | D17: BK1005 | E17: 12 | F17: 15.79 | G17: 12 | H17: 189.48 | I17: 397.56 | J17: =(Table1[[#This Row],[unit price]]*Table1[[#This Row],[quantity]]) -> 144 | K17: =(Table1[[#This Row],[extend price]]-Table1[[#This Row],[extend cost ]]) -> 208.08 | L17: Train to Pakistan | M17: Khushwant Singh | N17: Novel | O17: Penguin Books (India) | P17: 190 | Q17: 1st Edition | R17: In Stock | S17: 4 | T17: 11
A18: 43466 | B18: YYC-WH | C18: YYC-NW | D18: BK1005 | E18: 9 | F18: 15.79 | G18: 9 | H18: 142.11 | I18: 298.17 | J18: =(Table1[[#This Row],[unit price]]*Table1[[#This Row],[quantity]]) -> 81 | K18: =(Table1[[#This Row],[extend price]]-Table1[[#This Row],[extend cost ]]) -> 156.06 | L18: One Hundred Years of Solitude | M18: Gabriel Garcia Marquez | N18: Novel | O18: Penguin Books (India) | P18: 422 | Q18: 5th Edition | R18: In Stock | S18: 7 | T18: 23
A19: 43466 | B19: YYC-WH | C19: YYC-SE | D19: BK1005 | E19: 13 | F19: 15.79 | G19: 13 | H19: 205.27 | I19: 430.69 | J19: =(Table1[[#This Row],[unit price]]*Table1[[#This Row],[quantity]]) -> 169 | K19: =(Table1[[#This Row],[extend price]]-Table1[[#This Row],[extend cost ]]) -> 225.42 | L19: A Thousand Splendid Suns | M19: Khaled Hosseini | N19: Novel | O19: Bloomsbury Publishing (India) | P19: 419 | Q19: 1st Edition | R19: In Stock | S19: 8 | T19: 27
... A34: 43466 | B34: YYC-WH | C34: YYC-SE | D34: BK1010 | E34: 7 | F34: 12.96 | G34: 7 | H34: 90.72 | I34: 177.31 | J34: =(Table1[[#This Row],[unit price]]*Table1[[#This Row],[quantity]]) -> 49 | K34: =(Table1[[#This Row],[extend price]]-Table1[[#This Row],[extend cost ]]) -> 86.59 | L34: Who Moved My Cheese? | M34: Spencer Johnson | N34: Self-help and meditation | O34: Vermilion London (India) | P34: 96 | Q34: Published | R34: In Stock | S34: 40 | T34: 55
A35: 43466 | B35: YYC-WH | C35: YYC-DT | D35: BK1011 | E35: 15 | F35: 7.1 | G35: 15 | H35: 106.5 | I35: 197.85 | J35: =(Table1[[#This Row],[unit price]]*Table1[[#This Row],[quantity]]) -> 225 | K35: =(Table1[[#This Row],[extend price]]-Table1[[#This Row],[extend cost ]]) -> 91.35 | L35: Think and Grow Rich | M35: Napoleon Hill | N35: Self-help and meditation | O35: Amazing Reads (India) | P35: 332 | Q35: 1st Published | R35: In Stock | S35: 50+ | T35: 50
A36: 43466 | B36: YYC-WH | C36: YYC-NW | D36: BK1011 | E36: 8 | F36: 7.1 | G36: 8 | H36: 56.8 | I36: 105.52 | J36: =(Table1[[#This Row],[unit price]]*Table1[[#This Row],[quantity]]) -> 64 | K36: =(Table1[[#This Row],[extend price]]-Table1[[#This Row],[extend cost ]]) -> 48.72 | L36: The Power of Your Subconscious Mind | M36: Dr. Joseph Murphy | N36: Self-help and meditation | O36: Amazing Reads (India) | P36: 312 | Q36: Edition | R36: In Stock | S36: 0 | T36: 35
A37: 43466 | B37: YYC-WH | C37: YYC-SE | D37: BK1011 | E37: 11 | F37: 7.1 | G37: 11 | H37: 78.1 | I37: 145.09 | J37: =(Table1[[#This Row],[unit price]]*Table1[[#This Row],[quantity]]) -> 121 | K37: =(Table1[[#This Row],[extend price]]-Table1[[#This Row],[extend cost ]]) -> 66.99 | L37: How To Talk To Anyone | M37: Leil Lowndes | N37: Self-help and meditation | O37: Harper Element (India) | P37: 352 | Q37: 1st | R37: In Stock | S37: 37 | T37: 5
A38: 43466 | B38: YYC-WH | C38: YYC-DT | D38: BK1012 | E38: 19 | F38: 16.53 | G38: 19 | H38: 314.07 | I38: 714.97 | J38: =(Table1[[#This Row],[unit price]]*Table1[[#This Row],[quantity]]) -> 361 | K38: =(Table1[[#This Row],[extend price]]-Table1[[#This Row],[extend cost ]]) -> 400.9 | L38: How To Instantly Connect With Anyone | M38: Leil Lowndes | N38: Self-help and meditation | O38: McGraw-Hill (India) | P38: 336 | Q38: 1st Edition | R38: In Stock | S38: 0 | T38: 0
A39: 43466 | B39: YYC-WH | C39: YYC-NW | D39: BK1012 | E39: 14 | F39: 16.53 | G39: 14 | H39: 231.42 | I39: 526.82 | J39: =(Table1[[#This Row],[unit price]]*Table1[[#This Row],[quantity]]) -> 196 | K39: =(Table1[[#This Row],[extend price]]-Table1[[#This Row],[extend cost ]]) -> 295.4 | L39: Winning | M39: Jack Welch, Suzy Welch | N39: Self-help and meditation | O39: Harpercollins Publishers (India) | P39: 372 | Q39: 16th Impression | R39: In Stock | S39: 2 | T39: 27
A40: 43466 | B40: YYC-WH | C40: YYC-SE | D40: BK1012 | E40: 10 | F40: 16.53 | G40: 10 | H40: 165.3 | I40: 376.3 | J40: =(Table1[[#This Row],[unit price]]*Table1[[#This Row],[quantity]]) -> 100 | K40: =(Table1[[#This Row],[extend price]]-Table1[[#This Row],[extend cost ]]) -> 211 | L40: The Art of War | M40: Sun Tzu | N40: War Tactics and Foreign Policy | O40: Fingerprint Publishing (India) | P40: 100 | Q40: 1st Edition | R40: In Stock | S40: 11 | T40: 1
A41: 43466 | B41: YYC-WH | C41: YYC-DT | D41: BK1013 | E41: 18 | F41: 9.19 | G41: 18 | H41: 165.42 | I41: 373.5 | J41: =(Table1[[#This Row],[unit price]]*Table1[[#This Row],[quantity]]) -> 324 | K41: =(Table1[[#This Row],[extend price]]-Table1[[#This Row],[extend cost ]]) -> 208.08 | L41: Harry Potter and the Philosophers Stone (1997) | M41: J. K. Rowling | N41: Mystery, Detective, Thriller and Adventure | O41: Bloomsbury Publishing (India) | P41: 352 | Q41: New Edition | R41: In Stock | S41: 5 | T41: 40

Sheet 03_Documentation
A1: book store documentation
B5: PROJECT OVERVIEW
B6: PROJECT NAME | C6: BOOK STORE MANAGEMENT PROJECT | D6: CREATOR | E6: ARPITA
B7: VERSION | C7: 2.O | D7: PROJECT TYPE | E7: EXCEL MANAGEMENT
B8: STATUS | C8: COMPLETED | D8: LAST UPDATED
B10: PROJECT OBJECTIVE
B16: REQUIREMENT
B18: ID | C18: FEATURE | D18: DISCRIPTION | E18: PRIORITY | F18: STATUS
B19: REQ-01 | C19: SALES ANALYSIS | D19: ANALYSIS OF PROFIT AND QUANTITY | E19: HIGH | F19: COMPLETED
B20: REQ-02 | C20: PIVOT TABELS | D20: TABELS AND CHART | E20: HIGH | F20: COMPLETED
B21: REQ-03 | C21: DASH BOARD | D21: KPI CARDS AND CHART , 3D MODELS | E21: HIGH | F21: COMPLETED
B22: REQ-04 | C22: BUSINESS INSIGHT | D22: KEY FINDING FROM DATA | E22: MEDIUM | F22: COMPLETED
B23: REQ-05 | C23: INTERATIVE FILTER | D23: SLICERS AND FREEZ | E23: MEDIUM | F23: COMPLETED
B26: EXCEL SKILLS DEMONSTRATED
B28: PIVOT TABEL
B29: PIVOT CHART TABEL
B30: X;OOKUP
B31: FILTER
B32: SORTING
B33: UNIQUE
B34: DATA VALIDATIION
B35: CONDITIONAL FORMATTING
B36: FORMULAS
B37: SLICERS
B38: TIMELINES
... B40: DESIGN

Sheet 04-SALES RECORD
A1: book store sales report
A4: DATE | B4: ORDER ID | C4: BOOK NAME | D4: CATEGORY | E4: QUANTITY | F4: UNIT PRICE | G4: UNIT COST | H4: UNIT PROFIT | I4: TOTAL PROFIT | J4: profit % | K4: TOTAL SALES
A5: 43466 | B5: BK1000 | C5: Sapiens A Brief History Of Humankind | D5: History and Tradition+D5:D44 | E5: 19 | F5: 19 | G5: 8.09 | H5: =(Table3[[#This Row],[UNIT PRICE]]-Table3[[#This Row],[UNIT COST ]]) -> 10.91 | I5: =(Table3[[#This Row],[UNIT PROFIT ]]*Table3[[#This Row],[QUANTITY ]]) -> 207.29 | J5: =(Table3[[#This Row],[UNIT PROFIT ]]*Table3[[#This Row],[QUANTITY ]]) -> 207.29 | K5: =('02_Clean_Data'!E2*'02_Clean_Data'!G2) -> 361
A6: 43466 | B6: BK1000 | C6: The Intelligent Investor | D6: Business, Investment and Economics | E6: 10 | F6: 10 | G6: 8.09 | H6: =(Table3[[#This Row],[UNIT PRICE]]-Table3[[#This Row],[UNIT COST ]]) -> 1.91 | I6: =(Table3[[#This Row],[UNIT PROFIT ]]*Table3[[#This Row],[QUANTITY ]]) -> 19.1 | J6: =(Table3[[#This Row],[UNIT PROFIT ]]*Table3[[#This Row],[QUANTITY ]]) -> 19.1 | K6: =('02_Clean_Data'!E3*'02_Clean_Data'!G3) -> 100 | L6: Novel
A7: 43466 | B7: BK1000 | C7: Madinah Arabic Reader 1 | D7: Islamic Books | E7: 7 | F7: 7 | G7: 8.09 | H7: =(Table3[[#This Row],[UNIT PRICE]]-Table3[[#This Row],[UNIT COST ]]) -> -1.09 | I7: =(Table3[[#This Row],[UNIT PROFIT ]]*Table3[[#This Row],[QUANTITY ]]) -> -7.63 | J7: =(Table3[[#This Row],[UNIT PROFIT ]]*Table3[[#This Row],[QUANTITY ]]) -> -7.63 | K7: =('02_Clean_Data'!E4*'02_Clean_Data'!G4) -> 49 | ACX7: Row Labels | ACY7: Sum of TOTAL PROFIT | ADQ7: Row Labels | ADR7: Sum of TOTAL SALES
A8: 43466 | B8: BK1001 | C8: The Quran | D8: Islamic Books | E8: 21 | F8: 21 | G8: 10.75 | H8: =(Table3[[#This Row],[UNIT PRICE]]-Table3[[#This Row],[UNIT COST ]]) -> 10.25 | I8: =(Table3[[#This Row],[UNIT PROFIT ]]*Table3[[#This Row],[QUANTITY ]]) -> 215.25 | J8: =(Table3[[#This Row],[UNIT PROFIT ]]*Table3[[#This Row],[QUANTITY ]]) -> 215.25 | K8: =('02_Clean_Data'!E5*'02_Clean_Data'!G5) -> 441 | ACX8: Business, Investment and Economics | ACY8: 19.1 | ADQ8: Business, Investment and Economics | ADR8: 100
A9: 43466 | B9: BK1001 | C9: Let Us C, 19th Edition | D9: Computer Science & Engineering | E9: 13 | F9: 13 | G9: 10.75 | H9: =(Table3[[#This Row],[UNIT PRICE]]-Table3[[#This Row],[UNIT COST ]]) -> 2.25 | I9: =(Table3[[#This Row],[UNIT PROFIT ]]*Table3[[#This Row],[QUANTITY ]]) -> 29.25 | J9: =(Table3[[#This Row],[UNIT PROFIT ]]*Table3[[#This Row],[QUANTITY ]]) -> 29.25 | K9: =('02_Clean_Data'!E6*'02_Clean_Data'!G6) -> 169 | ACX9: Mystery, Detective, Thriller and Adventure | ACY9: 158.58 | ADQ9: Mystery, Detective, Thriller and Adventure | ADR9: 324
A10: 43466 | B10: BK1001 | C10: 400 Days | D10: Novel | E10: 6 | F10: 6 | G10: 10.75 | H10: =(Table3[[#This Row],[UNIT PRICE]]-Table3[[#This Row],[UNIT COST ]]) -> -4.75 | I10: =(Table3[[#This Row],[UNIT PROFIT ]]*Table3[[#This Row],[QUANTITY ]]) -> -28.5 | J10: =(Table3[[#This Row],[UNIT PROFIT ]]*Table3[[#This Row],[QUANTITY ]]) -> -28.5 | K10: =('02_Clean_Data'!E7*'02_Clean_Data'!G7) -> 36 | ACX10: Novel | ACY10: 3.8 | ADQ10: Novel | ADR10: 325
A11: 43466 | B11: BK1002 | C11: War And Peace | D11: Novel | E11: 17 | F11: 17 | G11: 15.1 | H11: =(Table3[[#This Row],[UNIT PRICE]]-Table3[[#This Row],[UNIT COST ]]) -> 1.9 | I11: =(Table3[[#This Row],[UNIT PROFIT ]]*Table3[[#This Row],[QUANTITY ]]) -> 32.3 | J11: =(Table3[[#This Row],[UNIT PROFIT ]]*Table3[[#This Row],[QUANTITY ]]) -> 32.3 | K11: =('02_Clean_Data'!E8*'02_Clean_Data'!G8) -> 289 | ACX11: Biographies, Memories & Interviews | ACY11: -28.2 | ADQ11: Biographies, Memories & Interviews | ADR11: 144
A12: 43466 | B12: BK1002 | C12: Ecotourism | D12: Tourism and Hospitality | E12: 9 | F12: 9 | G12: 15.1 | H12: =(Table3[[#This Row],[UNIT PRICE]]-Table3[[#This Row],[UNIT COST ]]) -> -6.1 | I12: =(Table3[[#This Row],[UNIT PROFIT ]]*Table3[[#This Row],[QUANTITY ]]) -> -54.9 | J12: =(Table3[[#This Row],[UNIT PROFIT ]]*Table3[[#This Row],[QUANTITY ]]) -> -54.9 | K12: =('02_Clean_Data'!E9*'02_Clean_Data'!G9) -> 81 | ACX12: Computer Science & Engineering | ACY12: 29.25 | ADQ12: Computer Science & Engineering | ADR12: 169
A13: 43466 | B13: BK1002 | C13: Managing Tourism and Hospitality Services | D13: Tourism and Hospitality | E13: 7 | F13: 7 | G13: 15.1 | H13: =(Table3[[#This Row],[UNIT PRICE]]-Table3[[#This Row],[UNIT COST ]]) -> -8.1 | I13: =(Table3[[#This Row],[UNIT PROFIT ]]*Table3[[#This Row],[QUANTITY ]]) -> -56.7 | J13: =(Table3[[#This Row],[UNIT PROFIT ]]*Table3[[#This Row],[QUANTITY ]]) -> -56.7 | K13: =('02_Clean_Data'!E10*'02_Clean_Data'!G10) -> 49 | ACX13: Foreign Language Books | ACY13: 139.65 | ADQ13: Foreign Language Books | ADR13: 441
A14: 43466 | B14: BK1003 | C14: Tata Stories | D14: Foreign Language Books | E14: 21 | F14: 21 | G14: 14.35 | H14: =(Table3[[#This Row],[UNIT PRICE]]-Table3[[#This Row],[UNIT COST ]]) -> 6.65 | I14: =(Table3[[#This Row],[UNIT PROFIT ]]*Table3[[#This Row],[QUANTITY ]]) -> 139.65 | J14: =(Table3[[#This Row],[UNIT PROFIT ]]*Table3[[#This Row],[QUANTITY ]]) -> 139.65 | K14: =('02_Clean_Data'!E11*'02_Clean_Data'!G11) -> 441 | ACX14: History and Tradition | ACY14: 207.29 | ADQ14: History and Tradition | ADR14: 361
A15: 43466 | B15: BK1003 | C15: Elon Musk | D15: Biographies, Memories & Interviews | E15: 12 | F15: 12 | G15: 14.35 | H15: =(Table3[[#This Row],[UNIT PRICE]]-Table3[[#This Row],[UNIT COST ]]) -> -2.35 | I15: =(Table3[[#This Row],[UNIT PROFIT ]]*Table3[[#This Row],[QUANTITY ]]) -> -28.2 | J15: =(Table3[[#This Row],[UNIT PROFIT ]]*Table3[[#This Row],[QUANTITY ]]) -> -28.2 | K15: =('02_Clean_Data'!E12*'02_Clean_Data'!G12) -> 144 | ACX15: International Politics | ACY15: -11.83 | ADQ15: International Politics | ADR15: 49
A16: 43466 | B16: BK1003 | C16: Sapiens A Brief History Of Humankind | D16: Business, Investment and Economics | E16: 10 | F16: 10 | G16: 14.35 | H16: =(Table3[[#This Row],[UNIT PRICE]]-Table3[[#This Row],[UNIT COST ]]) -> -4.35 | I16: =(Table3[[#This Row],[UNIT PROFIT ]]*Table3[[#This Row],[QUANTITY ]]) -> -43.5 | J16: =(Table3[[#This Row],[UNIT PROFIT ]]*Table3[[#This Row],[QUANTITY ]]) -> -43.5 | K16: =('02_Clean_Data'!E13*'02_Clean_Data'!G13) -> 100 | ACX16: Islamic Books | ACY16: 207.62 | ADQ16: Islamic Books | ADR16: 490
A17: 43466 | B17: BK1004 | C17: The Intelligent Investor | D17: Business, Investment and Economics | E17: 8 | F17: 8 | G17: 7.85 | H17: =(Table3[[#This Row],[UNIT PRICE]]-Table3[[#This Row],[UNIT COST ]]) -> 0.15 | I17: =(Table3[[#This Row],[UNIT PROFIT ]]*Table3[[#This Row],[QUANTITY ]]) -> 1.2 | J17: =(Table3[[#This Row],[UNIT PROFIT ]]*Table3[[#This Row],[QUANTITY ]]) -> 1.2 | K17: =('02_Clean_Data'!E14*'02_Clean_Data'!G14) -> 64 | ACX17: Novel | ACY17: -66.41 | ADQ17: Novel | ADR17: 1318
A18: 43466 | B18: BK1004 | C18: Madinah Arabic Reader 2 | D18: Business, Investment and Economics | E18: 12 | F18: 12 | G18: 7.85 | H18: =(Table3[[#This Row],[UNIT PRICE]]-Table3[[#This Row],[UNIT COST ]]) -> 4.15 | I18: =(Table3[[#This Row],[UNIT PROFIT ]]*Table3[[#This Row],[QUANTITY ]]) -> 49.8 | J18: =(Table3[[#This Row],[UNIT PROFIT ]]*Table3[[#This Row],[QUANTITY ]]) -> 49.8 | K18: =('02_Clean_Data'!E15*'02_Clean_Data'!G15) -> 144 | ACX18: Self-help and meditation | ACY18: 51 | ADQ18: Self-help and meditation | ADR18: 1327
A19: 43466 | B19: BK1004 | C19: The Quran | D19: Business, Investment and Economics | E19: 7 | F19: 7 | G19: 7.85 | H19: =(Table3[[#This Row],[UNIT PRICE]]-Table3[[#This Row],[UNIT COST ]]) -> -0.85 | I19: =(Table3[[#This Row],[UNIT PROFIT ]]*Table3[[#This Row],[QUANTITY ]]) -> -5.95 | J19: =(Table3[[#This Row],[UNIT PROFIT ]]*Table3[[#This Row],[QUANTITY ]]) -> -5.95 | K19: =('02_Clean_Data'!E16*'02_Clean_Data'!G16) -> 49 | ACX19: Tourism and Hospitality | ACY19: -111.6 | ADQ19: Tourism and Hospitality | ADR19: 130
... A21: 43466 | B21: BK1005 | C21: 401 Days | D21: Novel | E21: 9 | F21: 9 | G21: 15.79 | H21: =(Table3[[#This Row],[UNIT PRICE]]-Table3[[#This Row],[UNIT COST ]]) -> -6.79 | I21: =(Table3[[#This Row],[UNIT PROFIT ]]*Table3[[#This Row],[QUANTITY ]]) -> -61.11 | J21: =(Table3[[#This Row],[UNIT PROFIT ]]*Table3[[#This Row],[QUANTITY ]]) -> -61.11 | K21: =('02_Clean_Data'!E18*'02_Clean_Data'!G18) -> 81 | ACX21: Grand Total | ACY21: 532.95 | ADQ21: Grand Total | ADR21: 5278
A22: 43466 | B22: BK1005 | C22: War And Peace | D22: Novel | E22: 13 | F22: 13 | G22: 15.79 | H22: =(Table3[[#This Row],[UNIT PRICE]]-Table3[[#This Row],[UNIT COST ]]) -> -2.79 | I22: =(Table3[[#This Row],[UNIT PROFIT ]]*Table3[[#This Row],[QUANTITY ]]) -> -36.27 | J22: =(Table3[[#This Row],[UNIT PROFIT ]]*Table3[[#This Row],[QUANTITY ]]) -> -36.27 | K22: =('02_Clean_Data'!E19*'02_Clean_Data'!G19) -> 169
A23: 43466 | B23: BK1006 | C23: Ecotourism | D23: Self-help and meditation | E23: 10 | F23: 10 | G23: 8.69 | H23: =(Table3[[#This Row],[UNIT PRICE]]-Table3[[#This Row],[UNIT COST ]]) -> 1.31 | I23: =(Table3[[#This Row],[UNIT PROFIT ]]*Table3[[#This Row],[QUANTITY ]]) -> 13.1 | J23: =(Table3[[#This Row],[UNIT PROFIT ]]*Table3[[#This Row],[QUANTITY ]]) -> 13.1 | K23: =('02_Clean_Data'!E20*'02_Clean_Data'!G20) -> 100
A24: 43466 | B24: BK1006 | C24: Managing Tourism and Hospitality Services | D24: Self-help and meditation | E24: 4 | F24: 4 | G24: 8.69 | H24: =(Table3[[#This Row],[UNIT PRICE]]-Table3[[#This Row],[UNIT COST ]]) -> -4.69 | I24: =(Table3[[#This Row],[UNIT PROFIT ]]*Table3[[#This Row],[QUANTITY ]]) -> -18.76 | J24: =(Table3[[#This Row],[UNIT PROFIT ]]*Table3[[#This Row],[QUANTITY ]]) -> -18.76 | K24: =('02_Clean_Data'!E21*'02_Clean_Data'!G21) -> 16
A25: 43466 | B25: BK1006 | C25: Tata Stories | D25: Self-help and meditation | E25: 5 | F25: 5 | G25: 8.69 | H25: =(Table3[[#This Row],[UNIT PRICE]]-Table3[[#This Row],[UNIT COST ]]) -> -3.69 | I25: =(Table3[[#This Row],[UNIT PROFIT ]]*Table3[[#This Row],[QUANTITY ]]) -> -18.45 | J25: =(Table3[[#This Row],[UNIT PROFIT ]]*Table3[[#This Row],[QUANTITY ]]) -> -18.45 | K25: =('02_Clean_Data'!E22*'02_Clean_Data'!G22) -> 25
A26: 43466 | B26: BK1007 | C26: Elon Musk | D26: International Political Personality | E26: 11 | F26: 11 | G26: 8.69 | H26: =(Table3[[#This Row],[UNIT PRICE]]-Table3[[#This Row],[UNIT COST ]]) -> 2.31 | I26: =(Table3[[#This Row],[UNIT PROFIT ]]*Table3[[#This Row],[QUANTITY ]]) -> 25.41 | J26: =(Table3[[#This Row],[UNIT PROFIT ]]*Table3[[#This Row],[QUANTITY ]]) -> 25.41 | K26: =('02_Clean_Data'!E23*'02_Clean_Data'!G23) -> 121
A27: 43466 | B27: BK1007 | C27: Sapiens A Brief History Of Humankind | D27: International Politics | E27: 7 | F27: 7 | G27: 8.69 | H27: =(Table3[[#This Row],[UNIT PRICE]]-Table3[[#This Row],[UNIT COST ]]) -> -1.69 | I27: =(Table3[[#This Row],[UNIT PROFIT ]]*Table3[[#This Row],[QUANTITY ]]) -> -11.83 | J27: =(Table3[[#This Row],[UNIT PROFIT ]]*Table3[[#This Row],[QUANTITY ]]) -> -11.83 | K27: =('02_Clean_Data'!E24*'02_Clean_Data'!G24) -> 49
A28: 43466 | B28: BK1007 | C28: The Intelligent Investor | D28: Novel | E28: 7 | F28: 7 | G28: 8.69 | H28: =(Table3[[#This Row],[UNIT PRICE]]-Table3[[#This Row],[UNIT COST ]]) -> -1.69 | I28: =(Table3[[#This Row],[UNIT PROFIT ]]*Table3[[#This Row],[QUANTITY ]]) -> -11.83 | J28: =(Table3[[#This Row],[UNIT PROFIT ]]*Table3[[#This Row],[QUANTITY ]]) -> -11.83 | K28: =('02_Clean_Data'!E25*'02_Clean_Data'!G25) -> 49
A29: 43466 | B29: BK1008 | C29: Madinah Arabic Reader 3 | D29: Novel | E29: 15 | F29: 15 | G29: 12.44 | H29: =(Table3[[#This Row],[UNIT PRICE]]-Table3[[#This Row],[UNIT COST ]]) -> 2.56 | I29: =(Table3[[#This Row],[UNIT PROFIT ]]*Table3[[#This Row],[QUANTITY ]]) -> 38.4 | J29: =(Table3[[#This Row],[UNIT PROFIT ]]*Table3[[#This Row],[QUANTITY ]]) -> 38.4 | K29: =('02_Clean_Data'!E26*'02_Clean_Data'!G26) -> 225
A30: 43466 | B30: BK1008 | C30: The Quran | D30: Novel | E30: 1 | F30: 1 | G30: 12.44 | H30: =(Table3[[#This Row],[UNIT PRICE]]-Table3[[#This Row],[UNIT COST ]]) -> -11.44 | I30: =(Table3[[#This Row],[UNIT PROFIT ]]*Table3[[#This Row],[QUANTITY ]]) -> -11.44 | J30: =(Table3[[#This Row],[UNIT PROFIT ]]*Table3[[#This Row],[QUANTITY ]]) -> -11.44 | K30: =('02_Clean_Data'!E27*'02_Clean_Data'!G27) -> 1
A31: 43466 | B31: BK1008 | C31: Let Us C, 19th Edition | D31: Novel | E31: 4 | F31: 4 | G31: 12.44 | H31: =(Table3[[#This Row],[UNIT PRICE]]-Table3[[#This Row],[UNIT COST ]]) -> -8.44 | I31: =(Table3[[#This Row],[UNIT PROFIT ]]*Table3[[#This Row],[QUANTITY ]]) -> -33.76 | J31: =(Table3[[#This Row],[UNIT PROFIT ]]*Table3[[#This Row],[QUANTITY ]]) -> -33.76 | K31: =('02_Clean_Data'!E28*'02_Clean_Data'!G28) -> 16
A32: 43466 | B32: BK1009 | C32: 402 Days | D32: Novel | E32: 20 | F32: 20 | G32: 13.12 | H32: =(Table3[[#This Row],[UNIT PRICE]]-Table3[[#This Row],[UNIT COST ]]) -> 6.88 | I32: =(Table3[[#This Row],[UNIT PROFIT ]]*Table3[[#This Row],[QUANTITY ]]) -> 137.6 | J32: =(Table3[[#This Row],[UNIT PROFIT ]]*Table3[[#This Row],[QUANTITY ]]) -> 137.6 | K32: =('02_Clean_Data'!E29*'02_Clean_Data'!G29) -> 400
A33: 43466 | B33: BK1009 | C33: War And Peace | D33: Novel | E33: 13 | F33: 13 | G33: 13.12 | H33: =(Table3[[#This Row],[UNIT PRICE]]-Table3[[#This Row],[UNIT COST ]]) -> -0.12 | I33: =(Table3[[#This Row],[UNIT PROFIT ]]*Table3[[#This Row],[QUANTITY ]]) -> -1.56 | J33: =(Table3[[#This Row],[UNIT PROFIT ]]*Table3[[#This Row],[QUANTITY ]]) -> -1.56 | K33: =('02_Clean_Data'!E30*'02_Clean_Data'!G30) -> 169
... A44: 43466 | B44: BK1013 | C44: War And Peace | D44: Mystery, Detective, Thriller and Adventure | E44: 18 | F44: 18 | G44: 9.19 | H44: =(Table3[[#This Row],[UNIT PRICE]]-Table3[[#This Row],[UNIT COST ]]) -> 8.81 | I44: =(Table3[[#This Row],[UNIT PROFIT ]]*Table3[[#This Row],[QUANTITY ]]) -> 158.58 | J44: =(Table3[[#This Row],[UNIT PROFIT ]]*Table3[[#This Row],[QUANTITY ]]) -> 158.58 | K44: =('02_Clean_Data'!E41*'02_Clean_Data'!G41) -> 324
H45: =(Table3[[#This Row],[UNIT PRICE]]-Table3[[#This Row],[UNIT COST ]]) -> 0 | I45: =(Table3[[#This Row],[UNIT PROFIT ]]*Table3[[#This Row],[QUANTITY ]]) -> 0 | J45: =(Table3[[#This Row],[UNIT PROFIT ]]*Table3[[#This Row],[QUANTITY ]]) -> 0
A46: Total | C46: ALL | J46: =SUBTOTAL(109,Table3[profit %]) -> 559.91 | K46: =SUBTOTAL(109,Table3[[TOTAL SALES ]]) -> 5756

Sheet 05-INVENTORY RECORD 
A1: INVENTORY MANAGEMENT
A5: BOOK ID | B5: BOOK NAME | C5: author | D5: genre | E5: publication | F5: QUANTITY | G5: STOCK STATUS
A6: BK1000 | B6: Sapiens A Brief History Of Humankind | C6: Yuval Noah Harari | D6: History and Tradition+D6:D6:D27 | E6: Vintage Books (India) | F6: 19 | G6: =IF(F6>10,"IN STOCK ","LOW STOCK ") -> IN STOCK
A7: BK1000 | B7: The Intelligent Investor | C7: Benjamin Graham | D7: Business, Investment and Economics | E7: Harpercollins Publishers (India) | F7: 10 | G7: =IF(F7>10,"IN STOCK ","LOW STOCK ") -> LOW STOCK
A8: BK1000 | B8: Madinah Arabic Reader 1 | C8: Dr. V. Abdur Rahim | D8: Islamic Books | E8: Goodword Books (India) | F8: 7 | G8: =IF(F8>10,"IN STOCK ","LOW STOCK ") -> LOW STOCK
A9: BK1001 | B9: The Quran | C9: M.A.S. Abdel Haleem (Translator) | D9: Islamic Books | E9: Oxford University Press, USA | F9: 21 | G9: =IF(F9>10,"IN STOCK ","LOW STOCK ") -> IN STOCK
A10: BK1001 | B10: Let Us C, 19th Edition | C10: Yashavant Kanetkar | D10: Computer Science & Engineering | E10: BPB Publications (India) | F10: 13
A11: BK1001 | B11: 400 Days | C11: Chetan Bhagat | D11: Novel | E11: Westland (India) | F11: 6 | G11: =IF(F11>10,"IN STOCK ","LOW STOCK ") -> LOW STOCK
A12: BK1002 | B12: War And Peace | C12: Leo Tolstoy, Richard Pevear (Translator), Larissa Volokhonsky (Translator) | D12: Novel | E12: Vintage Classics (India) | F12: 17 | G12: =IF(F12>10,"IN STOCK ","LOW STOCK ") -> IN STOCK
A13: BK1002 | B13: Ecotourism | C13: Harish Bhat , B.S. Badan | D13: Tourism and Hospitality | E13: Cabi Publishing (India) | F13: 9 | G13: =IF(F13>10,"IN STOCK ","LOW STOCK ") -> LOW STOCK
A14: BK1002 | B14: Managing Tourism and Hospitality Services | C14: Gianna Moscardo (Editor), Bruce Prideaux (Editor), Eric Laws (Editor) | D14: Tourism and Hospitality | E14: Cabi Publishing (India) | F14: 7 | G14: =IF(F14>10,"IN STOCK ","LOW STOCK ") -> LOW STOCK
A15: BK1003 | B15: Tata Stories | C15: Harish Bhat | D15: Foreign Language Books | E15: Portfolio Penguin (India) | F15: 21 | G15: =IF(F15>10,"IN STOCK ","LOW STOCK ") -> IN STOCK
A16: BK1003 | B16: Elon Musk | C16: Walter Isaacson | D16: Biographies, Memories & Interviews | E16: Simon & Schuster Ltd (India) | F16: 12 | G16: =IF(F16>10,"IN STOCK ","LOW STOCK ") -> IN STOCK
A17: BK1003 | B17: Sapiens A Brief History Of Humankind | C17: R. Gopalakrishnan , M. Suresh Rao | D17: Business, Investment and Economics | E17: Rupa Publications India | F17: 10 | G17: =IF(F17>10,"IN STOCK ","LOW STOCK ") -> LOW STOCK
A18: BK1004 | B18: The Intelligent Investor | C18: Harish Bhat | D18: Business, Investment and Economics | E18: Penguin Business (India) | F18: 8 | G18: =IF(F18>10,"IN STOCK ","LOW STOCK ") -> LOW STOCK
A19: BK1004 | B19: Madinah Arabic Reader 2 | C19: Abhijit V. Banerjee , Esther Duflo | D19: Business, Investment and Economics | E19: Juggernaut (India) | F19: 12 | G19: =IF(F19>10,"IN STOCK ","LOW STOCK ") -> IN STOCK
A20: BK1004 | B20: The Quran | C20: Adam Smith | D20: Business, Investment and Economics | E20: Fingerprint Publishing (India) | F20: 7 | G20: =IF(F20>10,"IN STOCK ","LOW STOCK ") -> LOW STOCK
A21: BK1005 | B21: Let Us C, 19th Edition | C21: Khushwant Singh | D21: Novel | E21: Penguin Books (India) | F21: 12 | G21: =IF(F21>10,"IN STOCK ","LOW STOCK ") -> IN STOCK
A22: BK1005 | B22: 401 Days | C22: Gabriel Garcia Marquez | D22: Novel | E22: Penguin Books (India) | F22: 9 | G22: =IF(F22>10,"IN STOCK ","LOW STOCK ") -> LOW STOCK
... A45: BK1013 | B45: War And Peace | C45: J. K. Rowling | D45: Mystery, Detective, Thriller and Adventure | E45: Bloomsbury Publishing (India) | F45: 18 | G45: =IF(F45>10,"IN STOCK ","LOW STOCK ") -> IN STOCK

Sheet 06_Analysis
A1: book store SALES analysis
B6: TOTAL BOOK SOLD | F6: TOTAL REVENUE | J6: TOTAL PROFIT | M6: average order
B7: =SUM('04-SALES RECORD'!E5:E44) -> 438 | G7: =SUM('04-SALES RECORD'!K5:K44) -> 5756 | J7: =SUM('04-SALES RECORD'!I5:I44) -> 559.91
B9: Sales by Category
B12: Row Labels | C12: Total sales | D12: Total profit
B13: Novel | C13: 3058.69 | D13: 16.87
B14: Self-help and meditation | C14: 2672.91 | D14: 38.8
B15: Business, Investment and Economics | C15: 815.27 | D15: 82.32
B16: Novel | C16: 689.07 | D16: 82.44
B17: Islamic Books | C17: 646.73 | D17: 75.81
B18: Foreign Language Books | C18: 600.18 | D18: 298.83
B19: Tourism and Hospitality | C19: 510.24 | D19: 117.53
B20: War Tactics and Foreign Policy | C20: 376.3 | D20: 211
B21: Mystery, Detective, Thriller and Adventure | C21: 373.5 | D21: 208.08
B22: History and Tradition | C22: 359.48 | D22: 205.77
B23: Biographies, Memories & Interviews | C23: 342.96 | D23: 170.76
B24: Computer Science & Engineering | C24: 318.37 | D24: 178.62
... B27: International Politics | C27: 116.48 | D27: 55.65
B28: Formula1
B29: (blank)
B30: Grand Total | C30: 11252.42 | D30: 16.87
B32: Top Selling Books | I32: Most Profitabel Book
B35: BOOK NAME | C35: quantity sold | J35: Row Labels | K35: total profit
B36: The Quran | C36: 21 | J36: How To Instantly Connect With Anyone | K36: 400.9
B37: Tata Stories | C37: 21 | J37: The Alchemist | K37: 337.4
B38: The Alchemist | C38: 20 | J38: Tata Stories | K38: 298.83
B39: Sapiens A Brief History Of Humankind | C39: 19 | J39: Winning | K39: 295.4
B40: How To Instantly Connect With Anyone | C40: 19 | J40: The Quran | K40: 288.54
B41: Grand Total | C41: 100 | J41: Grand Total | K41: 1621.07

Sheet 05_Dashboard
A1: BOOK STORE MANAGEMENT DASHBOARD
B4: TOAL SALES | F4: TOTAL PROFIT | J4: PROFIT MARGIN | N4: AVERAGE SALES
AR8: {=_xlfn.UNIQUE('05-INVENTORY RECORD '!AR2:AR39)} -> 0 | AT8: ALL
AT10: Self-help and meditation | AU10: 2672.91 | AV10: 38.8
AT11: Business, Investment and Economics | AU11: 815.27 | AV11: 82.32
AT12: Novel | AU12: 689.07 | AV12: 82.44
AT13: Islamic Books | AU13: 646.73 | AV13: 75.81
AT14: Foreign Language Books | AU14: 600.18 | AV14: 298.83
AT15: Tourism and Hospitality | AU15: 510.24 | AV15: 117.53
AT16: War Tactics and Foreign Policy | AU16: 376.3 | AV16: 211
AT17: Mystery, Detective, Thriller and Adventure | AU17: 373.5 | AV17: 208.08
AT18: History and Tradition | AU18: 359.48 | AV18: 205.77
AT19: Biographies, Memories & Interviews | AU19: 342.96 | AV19: 170.76
AT20: Computer Science & Engineering | AU20: 318.37 | AV20: 178.62
AT21: Business, Investment and Economics | AU21: 189.2 | AV21: 108.3
... AT23: International Politics | AU23: 116.48 | AV23: 55.65
AT24: ALL

Sheet PIVOTS
A2: Sum of TOTAL SALES | B2: Sum of TOTAL PROFIT | C2: Sum of QUANTITY | F2: TOTAL ORDERS | G2: TOTAL SALES | H2: TOTAL PROFIT | I2: RATING
A3: 5278 | B3: 532.95 | C3: 390 | F3: =TEXT(C3,"#,##") -> 390 | G3: =A3 -> 5278 | H3: =B3 -> 532.95 | I3: =AVERAGE('01_Raw_Data'!W2:W41) -> 20.236842
A7: Row Labels | B7: Sum of TOTAL PROFIT | E7: Row Labels | F7: Sum of TOTAL SALES
A8: Business, Investment and Economics | B8: 19.1 | E8: Business, Investment and Economics | F8: 100 | I8: Row Labels | J8: Sum of Reviews
A9: Mystery, Detective, Thriller and Adventure | B9: 158.58 | E9: Mystery, Detective, Thriller and Adventure | F9: 324 | I9: Benjamin Graham | J9: 25
A10: Novel | B10: 3.8 | E10: Novel | F10: 325 | I10: Dale Carnegie | J10: 29
A11: Biographies, Memories & Interviews | B11: -28.2 | E11: Biographies, Memories & Interviews | F11: 144 | I11: Ernest Hemingway | J11: 54
A12: Computer Science & Engineering | B12: 29.25 | E12: Computer Science & Engineering | F12: 169 | I12: Napoleon Hill | J12: 26
A13: Foreign Language Books | B13: 139.65 | E13: Foreign Language Books | F13: 441 | I13: Spencer Johnson | J13: 25
A14: History and Tradition | B14: 207.29 | E14: History and Tradition | F14: 361 | I14: Grand Total | J14: 159
A15: International Politics | B15: -11.83 | E15: International Politics | F15: 49
A16: Islamic Books | B16: 207.62 | E16: Islamic Books | F16: 490
A17: Novel | B17: -66.41 | E17: Novel | F17: 1318
A18: Self-help and meditation | B18: 51 | E18: Self-help and meditation | F18: 1327
A19: Tourism and Hospitality | B19: -111.6 | E19: Tourism and Hospitality | F19: 130
A20: War Tactics and Foreign Policy | B20: -65.3 | E20: War Tactics and Foreign Policy | F20: 100
A21: Grand Total | B21: 532.95 | E21: Grand Total | F21: 5278
E28: Row Labels | F28: Sum of rating
A29: Row Labels | B29: Sum of QUANTITY | E29: Amazing Reads (India) | F29: 85 | I29: INDIA | J29: 85 | K29: Row Labels | L29: Sum of 85
A30: Business, Investment and Economics | B30: 10 | E30: Bloomsbury Publishing (India) | F30: 67 | I30: INDIA | J30: 67 | K30: EUROPE | L30: 111
A31: LOW STOCK | B31: 10 | E31: BPB Publications (India) | F31: 3 | I31: INDIA | J31: 3 | K31: INDIA | L31: 622
A32: Novel | B32: 6 | E32: Cabi Publishing (India) | F32: 1 | I32: INDIA | J32: 1 | K32: UK | L32: 10 | P32: Row Labels | Q32: Sum of Reviews
A33: LOW STOCK | B33: 6 | E33: Europa Editions | F33: 38 | I33: EUROPE | J33: 38 | K33: USA | L33: 19 | P33: Benjamin Graham | Q33: 25
A34: Business, Investment and Economics | B34: 25 | E34: Fingerprint Publishing (India) | F34: 91 | I34: INDIA | J34: 91 | K34: Grand Total | L34: 762 | P34: Chetan Bhagat | Q34: 19
A35: LOW STOCK | B35: 25 | E35: Friend's Book Corner | F35: 73 | I35: EUROPE | J35: 73 | P35: Dale Carnegie | Q35: 29
A36: International Politics | B36: 7 | E36: Goodword Books (India) | F36: 6 | I36: INDIA | J36: 6 | P36: Dr. Joseph Murphy | Q36: 17
A37: LOW STOCK | B37: 7 | E37: Harper Element (India) | F37: 5 | I37: INDIA | J37: 5 | P37: Ernest Hemingway | Q37: 54
A38: Islamic Books | B38: 7 | E38: Harpercollins Publishers (India) | F38: 133 | I38: INDIA | J38: 133 | P38: George Orwell | Q38: 17
A39: LOW STOCK | B39: 7 | E39: Juggernaut (India) | F39: 5 | I39: INDIA | J39: 5 | P39: J. K. Rowling | Q39: 22
A40: Novel | B40: 29 | E40: Maanu Graphics Publishers (India) | F40: 85 | I40: INDIA | J40: 85 | P40: Napoleon Hill | Q40: 26
A41: LOW STOCK | B41: 29 | E41: McGraw-Hill (India) | F41: 0 | I41: INDIA | J41: 0 | P41: Spencer Johnson | Q41: 25
A42: Self-help and meditation | B42: 41 | E42: Oxford University Press, USA | F42: 19 | I42: USA | J42: 19 | P42: Yuval Noah Harari | Q42: 16
A43: LOW STOCK | B43: 41 | E43: Penguin Books (India) | F43: 48 | I43: INDIA | J43: 48 | P43: Grand Total | Q43: 250
A44: Tourism and Hospitality | B44: 16 | E44: Penguin Business (India) | F44: 3 | I44: INDIA | J44: 3
A45: LOW STOCK | B45: 16 | E45: Portfolio Penguin (India) | F45: 2 | I45: INDIA | J45: 2
A46: War Tactics and Foreign Policy | B46: 10 | E46: Random House Business Books (India) | F46: 19 | I46: INDIA | J46: 19
A47: LOW STOCK | B47: 10 | E47: Random House UK | F47: 10 | I47: UK | J47: 10
A48: Grand Total | B48: 151 | E48: Rupa Publications India | F48: 1 | I48: INDIA | J48: 1
E49: Simon & Schuster Ltd (India) | F49: 2 | I49: INDIA | J49: 2
E50: Vermilion London (India) | F50: 81 | I50: INDIA | J50: 81
...

Sheet 07-DASHBOARD

Sheet 08-BUSINESS INSIGHT
A1: BOOK INSIGHT SHEET
E4: BookNest - Inventory Summary and Stock Insights
A7: TOTAL BOOK TITELS | D7: TOTAL QUANTITY | G7: LOW-STOCK BOOKS | J7: IN-STOCK BOOKS
A8: =COUNTA('04-SALES RECORD'!C5:C44) -> 40 | D8: =SUM('04-SALES RECORD'!E5:E44) -> 438 | G8: =SUMIF('05-INVENTORY RECORD '!F8:F45,"<8") -> 69 | J8: =SUMIF('05-INVENTORY RECORD '!F8:F45,">8") -> 316
B11: category insight
B13: CATEGORY | C13: QUANTITY | D13: BOOKK TITEL | E13: INSIGHTS
B14: {=_xlfn.UNIQUE('05-INVENTORY RECORD '!D8:D45)} -> Islamic Books | C14: =SUMIF('05-INVENTORY RECORD '!D$8:D$45, B14,'05-INVENTORY RECORD '!F$8:F$45) -> 28 | D14: =COUNTIF('05-INVENTORY RECORD '!D8:D45,B14) -> 2 | E14: moderate in stock
B15: Computer Science & Engineering | C15: =SUMIF('05-INVENTORY RECORD '!D$8:D$45, B15,'05-INVENTORY RECORD '!F$8:F$45) -> 13 | D15: =COUNTIF('05-INVENTORY RECORD '!D9:D46,B15) -> 1 | E15: {=_xlfn.IFS(C15>100,"high in stock",C15>50,"moderate in stock",C15<49,"low in stock ")} -> low in stock
B16: Novel | C16: =SUMIF('05-INVENTORY RECORD '!D$8:D$45, B16,'05-INVENTORY RECORD '!F$8:F$45) -> 23 | D16: =COUNTIF('05-INVENTORY RECORD '!D10:D47,B16) -> 2 | E16: {=_xlfn.IFS(C16>100,"high in stock",C16>50,"moderate in stock",C16<49,"low in stock ")} -> low in stock
B17: Tourism and Hospitality | C17: =SUMIF('05-INVENTORY RECORD '!D$8:D$45, B17,'05-INVENTORY RECORD '!F$8:F$45) -> 16 | D17: =COUNTIF('05-INVENTORY RECORD '!D11:D48,B17) -> 2 | E17: {=_xlfn.IFS(C17>100,"high in stock",C17>50,"moderate in stock",C17<49,"low in stock ")} -> low in stock
B18: Foreign Language Books | C18: =SUMIF('05-INVENTORY RECORD '!D$8:D$45, B18,'05-INVENTORY RECORD '!F$8:F$45) -> 21 | D18: =COUNTIF('05-INVENTORY RECORD '!D12:D49,B18) -> 1 | E18: {=_xlfn.IFS(C18>100,"high in stock",C18>50,"moderate in stock",C18<49,"low in stock ")} -> low in stock
B19: Biographies, Memories & Interviews | C19: =SUMIF('05-INVENTORY RECORD '!D$8:D$45, B19,'05-INVENTORY RECORD '!F$8:F$45) -> 12 | D19: =COUNTIF('05-INVENTORY RECORD '!D13:D50,B19) -> 1 | E19: {=_xlfn.IFS(C19>100,"high in stock",C19>50,"moderate in stock",C19<49,"low in stock ")} -> low in stock
B20: Business, Investment and Economics | C20: =SUMIF('05-INVENTORY RECORD '!D$8:D$45, B20,'05-INVENTORY RECORD '!F$8:F$45) -> 37 | D20: =COUNTIF('05-INVENTORY RECORD '!D14:D51,B20) -> 4 | E20: moderate in stock
B21: Novel | C21: =SUMIF('05-INVENTORY RECORD '!D$8:D$45, B21,'05-INVENTORY RECORD '!F$8:F$45) -> 102 | D21: =COUNTIF('05-INVENTORY RECORD '!D15:D52,B21) -> 10 | E21: {=_xlfn.IFS(C21>100,"high in stock",C21>50,"moderate in stock",C21<49,"low in stock ")} -> high in stock
B22: Self-help and meditation | C22: =SUMIF('05-INVENTORY RECORD '!D$8:D$45, B22,'05-INVENTORY RECORD '!F$8:F$45) -> 111 | D22: =COUNTIF('05-INVENTORY RECORD '!D16:D53,B22) -> 11 | E22: {=_xlfn.IFS(C22>100,"high in stock",C22>50,"moderate in stock",C22<49,"low in stock ")} -> high in stock
B23: International Political Personality | C23: =SUMIF('05-INVENTORY RECORD '!D$8:D$45, B23,'05-INVENTORY RECORD '!F$8:F$45) -> 11 | D23: =COUNTIF('05-INVENTORY RECORD '!D17:D54,B23) -> 1 | E23: {=_xlfn.IFS(C23>100,"high in stock",C23>50,"moderate in stock",C23<49,"low in stock ")} -> low in stock
B24: International Politics | C24: =SUMIF('05-INVENTORY RECORD '!D$8:D$45, B24,'05-INVENTORY RECORD '!F$8:F$45) -> 7 | D24: =COUNTIF('05-INVENTORY RECORD '!D18:D55,B24) -> 1 | E24: {=_xlfn.IFS(C24>100,"high in stock",C24>50,"moderate in stock",C24<49,"low in stock ")} -> low in stock
B25: War Tactics and Foreign Policy | C25: =SUMIF('05-INVENTORY RECORD '!D$8:D$45, B25,'05-INVENTORY RECORD '!F$8:F$45) -> 10 | D25: =COUNTIF('05-INVENTORY RECORD '!D19:D56,B25) -> 1 | E25: {=_xlfn.IFS(C25>100,"high in stock",C25>50,"moderate in stock",C25<49,"low in stock ")} -> low in stock
B26: Mystery, Detective, Thriller and Adventure | C26: =SUMIF('05-INVENTORY RECORD '!D$8:D$45, B26,'05-INVENTORY RECORD '!F$8:F$45) -> 18 | D26: =COUNTIF('05-INVENTORY RECORD '!D20:D57,B26) -> 1 | E26: {=_xlfn.IFS(C26>100,"high in stock",C26>50,"moderate in stock",C26<49,"low in stock ")} -> low in stock
C29: stock alrt
B31: BOOK name | C31: AUTHOR | D31: QUANTITY | E31: ALERT
B32: {=_xlfn.XLOOKUP(D32:D36,C14:C26,B14:B26)} -> Computer Science & Engineering | C32: {=_xlfn.XLOOKUP(B32:B36,'05-INVENTORY RECORD '!D8:D45,'05-INVENTORY RECORD '!C8:C45)} -> Yashavant Kanetkar | D32: 13 | E32: LOW STOCK
B33: Biographies, Memories & Interviews | C33: Walter Isaacson | D33: 12 | E33: LOW STOCK
B34: International Political Personality | C34: Adolf Hitler | D34: 11 | E34: LOW STOCK
B35: International Politics | C35: Fareed Zakaria | D35: 7 | E35: RED ALERT
B36: War Tactics and Foreign Policy | C36: Sun Tzu | D36: 10 | E36: RED ALERT
